<?xml version="1.0"?>
<robot name="piper_six_dof">
  <link name="base_link">
    <inertial><origin xyz="0 0 0" rpy="0 0 0"/><mass value="1"/><inertia ixx="1e-3" ixy="0" ixz="0" iyy="1e-3" iyz="0" izz="1e-3"/></inertial>
    <visual><origin xyz="0 0 0" rpy="0 0 0"/><geometry><box size="0.08 0.08 0.04"/></geometry></visual>
    <collision><origin xyz="0 0 0" rpy="0 0 0"/><geometry><box size="0.08 0.08 0.04"/></geometry></collision>
  </link>
  <link name="link1"><visual><origin xyz="0 0 0.05"/><geometry><box size="0.05 0.05 0.1"/></geometry></visual><collision><origin xyz="0 0 0.05"/><geometry><box size="0.05 0.05 0.1"/></geometry></collision></link>
  <joint name="joint1" type="revolute"><parent link="base_link"/><child link="link1"/><origin xyz="0 0 0.02"/><axis xyz="0 0 1"/><limit lower="-3.14" upper="3.14" effort="10" velocity="2.0"/></joint>
  <link name="link2"><visual><origin xyz="0 0 0.08"/><geometry><box size="0.05 0.05 0.16"/></geometry></visual><collision><origin xyz="0 0 0.08"/><geometry><box size="0.05 0.05 0.16"/></geometry></collision></link>
  <joint name="joint2" type="revolute"><parent link="link1"/><child link="link2"/><origin xyz="0 0 0.1"/><axis xyz="0 1 0"/><limit lower="-2.1" upper="2.1" effort="10" velocity="2.0"/></joint>
  <link name="link3"><visual><origin xyz="0 0 0.08"/><geometry><box size="0.05 0.05 0.16"/></geometry></visual><collision><origin xyz="0 0 0.08"/><geometry><box size="0.05 0.05 0.16"/></geometry></collision></link>
  <joint name="joint3" type="revolute"><parent link="link2"/><child link="link3"/><origin xyz="0 0 0.16"/><axis xyz="0 1 0"/><limit lower="-2.8" upper="2.8" effort="10" velocity="2.0"/></joint>
  <link name="link4"><visual><origin xyz="0 0 0.06"/><geometry><box size="0.045 0.045 0.12"/></geometry></visual><collision><origin xyz="0 0 0.06"/><geometry><box size="0.045 0.045 0.12"/></geometry></collision></link>
  <joint name="joint4" type="revolute"><parent link="link3"/><child link="link4"/><origin xyz="0 0 0.16"/><axis xyz="1 0 0"/><limit lower="-3.14" upper="3.14" effort="10" velocity="2.0"/></joint>
  <link name="link5"><visual><origin xyz="0 0 0.04"/><geometry><box size="0.04 0.04 0.08"/></geometry></visual><collision><origin xyz="0 0 0.04"/><geometry><box size="0.04 0.04 0.08"/></geometry></collision></link>
  <joint name="joint5" type="revolute"><parent link="link4"/><child link="link5"/><origin xyz="0 0 0.12"/><axis xyz="0 1 0"/><limit lower="-3.14" upper="3.14" effort="10" velocity="2.0"/></joint>
  <link name="link6"><visual><origin xyz="0 0 0.03"/><geometry><box size="0.035 0.035 0.06"/></geometry></visual><collision><origin xyz="0 0 0.03"/><geometry><box size="0.035 0.035 0.06"/></geometry></collision></link>
  <joint name="joint6" type="revolute"><parent link="link5"/><child link="link6"/><origin xyz="0 0 0.08"/><axis xyz="0 0 1"/><limit lower="-3.14" upper="3.14" effort="10" velocity="2.0"/></joint>
  <link name="gripper_base"><visual><origin xyz="0 0 0.02"/><geometry><box size="0.03 0.03 0.04"/></geometry></visual><collision><origin xyz="0 0 0.02"/><geometry><box size="0.03 0.03 0.04"/></geometry></collision></link>
  <joint name="ee_fixed" type="fixed"><parent link="link6"/><child link="gripper_base"/><origin xyz="0 0 0.06"/></joint>
</robot>
